[2022-08-29T15:08:03.178-0400] {taskinstance.py:1171} INFO - Dependencies all met for <TaskInstance: dag_with_python_operator_v04.greet manual__2022-08-29T19:07:56.518097+00:00 [queued]>
[2022-08-29T15:08:03.195-0400] {taskinstance.py:1171} INFO - Dependencies all met for <TaskInstance: dag_with_python_operator_v04.greet manual__2022-08-29T19:07:56.518097+00:00 [queued]>
[2022-08-29T15:08:03.195-0400] {taskinstance.py:1368} INFO - 
--------------------------------------------------------------------------------
[2022-08-29T15:08:03.195-0400] {taskinstance.py:1369} INFO - Starting attempt 1 of 6
[2022-08-29T15:08:03.195-0400] {taskinstance.py:1370} INFO - 
--------------------------------------------------------------------------------
[2022-08-29T15:08:03.249-0400] {taskinstance.py:1389} INFO - Executing <Task(PythonOperator): greet> on 2022-08-29 19:07:56.518097+00:00
[2022-08-29T15:08:03.252-0400] {standard_task_runner.py:52} INFO - Started process 3924 to run task
[2022-08-29T15:08:03.256-0400] {standard_task_runner.py:79} INFO - Running: ['airflow', 'tasks', 'run', 'dag_with_python_operator_v04', 'greet', 'manual__2022-08-29T19:07:56.518097+00:00', '--job-id', '3', '--raw', '--subdir', '/home/augenz/PycharmProjects/airflow/dags/dag_with_python_operator_v04.py', '--cfg-path', '/run/user/1000/app/com.jetbrains.PyCharm-Community/tmptgilgzmy', '--error-file', '/run/user/1000/app/com.jetbrains.PyCharm-Community/tmpgb_yicep']
[2022-08-29T15:08:03.258-0400] {standard_task_runner.py:80} INFO - Job 3: Subtask greet
[2022-08-29T15:08:03.434-0400] {task_command.py:371} INFO - Running <TaskInstance: dag_with_python_operator_v04.greet manual__2022-08-29T19:07:56.518097+00:00 [running]> on host pop-os.localdomain
[2022-08-29T15:08:03.639-0400] {taskinstance.py:1581} INFO - Exporting the following env vars:
AIRFLOW_CTX_DAG_OWNER=admin
AIRFLOW_CTX_DAG_ID=dag_with_python_operator_v04
AIRFLOW_CTX_TASK_ID=greet
AIRFLOW_CTX_EXECUTION_DATE=2022-08-29T19:07:56.518097+00:00
AIRFLOW_CTX_TRY_NUMBER=1
AIRFLOW_CTX_DAG_RUN_ID=manual__2022-08-29T19:07:56.518097+00:00
[2022-08-29T15:08:03.641-0400] {taskinstance.py:1902} ERROR - Task failed with exception
Traceback (most recent call last):
  File "/home/augenz/PycharmProjects/airflow/.env_airflow/lib/python3.9/site-packages/airflow/operators/python.py", line 171, in execute
    return_value = self.execute_callable()
  File "/home/augenz/PycharmProjects/airflow/.env_airflow/lib/python3.9/site-packages/airflow/operators/python.py", line 189, in execute_callable
    return self.python_callable(*self.op_args, **self.op_kwargs)
  File "/home/augenz/PycharmProjects/airflow/dags/dag_with_python_operator_v04.py", line 14, in greet
    name = ti.xcoms_pull(task_ids='get_name')
AttributeError: 'TaskInstance' object has no attribute 'xcoms_pull'
[2022-08-29T15:08:03.671-0400] {taskinstance.py:1407} INFO - Marking task as UP_FOR_RETRY. dag_id=dag_with_python_operator_v04, task_id=greet, execution_date=20220829T190756, start_date=20220829T190803, end_date=20220829T190803
[2022-08-29T15:08:03.715-0400] {standard_task_runner.py:92} ERROR - Failed to execute job 3 for task greet ('TaskInstance' object has no attribute 'xcoms_pull'; 3924)
[2022-08-29T15:08:03.750-0400] {local_task_job.py:156} INFO - Task exited with return code 1
[2022-08-29T15:08:03.873-0400] {local_task_job.py:279} INFO - 0 downstream tasks scheduled from follow-on schedule check
